Workbook
Name AcumReaj: [1]Reajustes!$N$5:$S$59
Name AvAcum: '[1]Avances Acumulados'!$A$8:$BI$210
Name Descuentos: 'CARATULA EP '!#REF!
Name Descuentos: 'CARATULA EP '!#REF!
Name EP: 'CARATULA EP '!#REF!
Name EP: 'CARATULA EP '!#REF!
Name Periodo: 'CARATULA EP '!#REF!
Name Periodo: 'CARATULA EP '!#REF!
Name Retenciones: [1]Retenciones!$A$4:$G$193

Sheet PORTADA
E10: Servicios xxxxxxxxxx
E11: Contrato N° xxxxxxxxx
F14: xxxxx
F18: ODS | G18: N° | H18: 1
D21: Levantamiento Nube de Puntos Cañerias Sistema Enfriamiento Motor Anillo y Ciclo Conversor Molino Unitario Nº2
C24: Revisión 1
C25: ESTADO DE PAGO | H25: 1
C26: xxxx

Sheet CARATULA EP 
J5: Formulario
J7: N° DOC : xxxxxxx
E8: FORMULARIO | J8: Rev : 01
J9: Vigencia : 10-07-2026
J10: Pag. : 1 de 2
E11: CARÁTULA ESTADO DE PAGO
B13: FORMULARIO CARÁTULA ESTADO DE PAGO
B17: =+CONCATENATE("E S T A D O D E P A G O N ° ",E19," - O D S N ° ",H19) -> E S T A D O D E P A G O N ° 1 - O D S N ° 1
C19: Estado de Pago: | E19: =+PORTADA!H25 -> 1 | G19: ODS N° | H19: =+PORTADA!H18 -> 1
C20: Periodo: | D20: 44915 | E20: - | F20: 44977
C21: Mes: | D21: =F20 -> 44977
C23: EMPRESA CONTRATISTA : | F23: xxxxxx
C24: RUT : | F24: xxxxxx
C25: NOMBRE SERVICIOS: | F25: Levantamiento Nube de Puntos Cañerias Sistema Enfriamiento Motor Anillo y Ciclo Conversor Molino Unitario Nº2
C26: CONTRATO : | F26: xxxxxxxxxxxxxxxxxxxxxxxxxxxxxxxxxxxxxxxxxxxxxxxx
C27: FECHA INICIACIÓN : | E27: 44880 | G27: PLAZO EJECUCIÓN:
C28: FECHA DE INICIO: | E28: 44896
C29: FECHA DE TERMINO: | E29: 45291
C30: VALOR CONTRATO INICIAL | I30: : $ | J30: =+'EDP 001'!G47 -> 7282646
C31: AUMENTO Y DISMINUCIONES DEL CONTRATO (NOC-1) | I31: : $ | J31: =+'NOC-1'!K36 -> 2511023
C32: AUMENTO Y DISMINUCIONES DEL CONTRATO (NOC-2) | I32: : $ | J32: 0
C33: VALOR VIGENTE DEL CONTRATO | I33: : $ | J33: =+J30+J31+J32 -> 9793669
C35: VALOR COBRADO HASTA LA FECHA ( SIN REAJUSTES ) | I35: : $ | J35: =+'EDP 001'!N47 -> 9793669.3
C36: ="VALOR PAGADO AL ESTADO DE PAGO ANTERIOR N°"&" "&(E19-1) -> VALOR PAGADO AL ESTADO DE PAGO ANTERIOR N° 0 | I36: : $ | J36: 0
C38: VALOR DEL PRESENTE ESTADO DE PAGO ( SIN REAJUSTES ) | I38: : $ | J38: =+'EDP 001'!P47 -> 9793669.3
C39: VALOR AFECTO A REAJUSTE | I39: : $ | J39: =+J38 -> 9793669.3
C40: VALOR NO AFECTO A REAJUSTE | I40: : $ | J40: =J38-J39 -> 0 | M40: =+J39+J40 -> 9793669.3
C43: REAJUSTES
C44: REAJUSTES PARA ESTE ESTADO DE PAGO (0%) | I44: : $ | J44: =+J39*N44 -> 0 | N44: 0
C45: VALOR AFECTO A REAJUSTE | I45: : $ | J45: =+J39 -> 9793669.3
C46: TOTAL REAJUSTES ACUMULADOS | I46: : $ | J46: =+J45+J44 -> 9793669.3
C48: VALOR DEL PRESENTE ESTADO DE PAGO ( CON REAJUSTES ) | I48: : $ | J48: =J38+J44 -> 9793669.3
C50: OTROS DESCUENTOS | F50: (No Aplica al presente EP) | I50: : $ | J50: 0
C53: TOTAL NETO A PAGAR | I53: : $ | J53: =+J48+J50 -> 9793669.3
C54: IVA 19 % | I54: : $ | J54: =+J53*N54 -> 1860797.2 | N54: 0.19
C55: TOTAL A FACTURAR | I55: : $ | J55: =+J54+J53 -> 11654466
C60: son: | D60: Once millones seiscientos cincuenta y cuatro mil cuatrocientos sesenta y seis pesos
C69: xxxxxxxxxxx | I69: xxxxxxxxxxx
C70: ADMINISTRADOR DE CONTRATOSx | I70: Jefe de Proyecto

Sheet EDP 001
R5: N° DOC: | T5: xxxxxxxxxx
E6: FORMULARIO | R6: Rev: | T6: 01
R7: Vigencia: | T7: 46213
E8: ESTADO DE PAGO | K8: N° | L8: =+'CARATULA EP '!E19 -> 1 | R8: Página: | T8: 2 de 2
C11: Estado de Pago N° | D11: ='CARATULA EP '!E19 -> 1
C12: Mes | D12: ='CARATULA EP '!D21 -> 44977
B14: CONTRATO: | D14: =+'CARATULA EP '!F26 -> xxxxxxxxxxxxxxxxxxxxxxxxxxxxxxxxxxxxxxxxxxxxxxxx | P14: Fecha de Presentación : | R14: =+T15 -> 44977
B15: CONTRATISTA: | D15: =+'CARATULA EP '!F23 -> xxxxxx | P15: Periodo de Pago : | R15: ='CARATULA EP '!D20 -> 44915 | S15: - | T15: ='CARATULA EP '!F20 -> 44977
B16: DESCRIPCIÓN SERVICIO: | D16: Levantamiento Nube de Puntos Cañerias Sistema Enfriamiento Motor Anillo y Ciclo Conversor Molino Unitario Nº2 | P16: Moneda : | R16: Pesos
D18: CONTRATO BASE | H18: MODIFICACIONES AUTORIZADAS | K18: AVANCE FISICO DE LAS PARTIDAS | N18: AVANCE FINANCIERO | Q18: AVANCE PORCENTUAL (%)
B19: ITEM | C19: DESCRIPCION | F19: Precio | I19: Precio | K19: Acumulados | M19: Presente | N19: Acumulados | P19: Presente | Q19: Acumulados
D20: Unidad | E20: Cantidad | F20: Precio | G20: Total | H20: Cantidad | I20: Unitario | J20: Total | K20: A la fecha | L20: Anterior EDP N°0 | M20: E.P. N° 01 | N20: A la fecha | O20: =L20 -> Anterior EDP N°0 | P20: =M20 -> E.P. N° 01 | Q20: Al EP anterior (%) | R20: Acum. a la Fecha (%) | S20: Presente EP (%) | T20: Saldo Contrato | V20: Fisco
B21: I | C21: CONTRATO BASE | G21: =SUM(G23:G46) -> 7282646 | J21: =+J23+J25+J31+J42+J32+J33 -> 7809381.3 | N21: =SUM(N23:N46) -> 9793669.3 | O21: =SUM(O23:O46) -> 0 | P21: =+P23+P25+P30+P31+P32+P35+P42+P37+P34 -> 9793669.3 | T21: =SUM(T23:T46) -> 0
B22: 1 | C22: SERVICIOS PROFESIONALES
B23: 1.1 | C23: Ingeniero Geomensor | D23: HH | E23: 110 | F23: 30379 | G23: =E23*F23 -> 3341690 | H23: =+'NOC-1'!L11 -> 150 | J23: =+H23*F23 -> 4556850 | K23: =+L23+M23 -> 150 | L23: 0 | M23: 150 | N23: =+O23+P23 -> 4556850 | O23: 0 | P23: =M23*F23 -> 4556850 | Q23: =+O23/G$23 -> 0 | R23: =+N23/J$23 -> 1 | S23: =+P23/J$23 -> 1 | T23: =+J23-N23 -> 0 | V23: =+H23-K23 -> 0 | W23: =+V23+K23 -> 150
B24: 1.2 | C24: Topógrafo | D24: HH | E24: 0 | F24: 22998 | G24: =E24*F24 -> 0 | K24: =+L24+M24 -> 0 | L24: 0 | M24: 0 | N24: =+K24*F24 -> 0 | O24: =+F24*L24 -> 0 | P24: =M24*F24 -> 0 | Q24: =+O24/G$23 -> 0 | R24: =+N24/G$23 -> 0 | S24: =+P24/G$23 -> 0 | T24: =+J24-N24 -> 0 | V24: =+H24-K24 -> 0
B25: 1.3 | C25: Alarife | D25: HH | E25: 120 | F25: 14773 | G25: =E25*F25 -> 1772760 | H25: =+'NOC-1'!L13 -> 160 | J25: =+H25*F25 -> 2363680 | K25: =+L25+M25 -> 160 | L25: 0 | M25: 160 | N25: =+O25+P25 -> 2363680 | O25: =+F25*L25 -> 0 | P25: =M25*F25 -> 2363680 | Q25: =+O25/F$25 -> 0 | R25: =+N25/J$25 -> 1 | S25: =+P25/J$25 -> 1 | T25: =+J25-N25 -> 0 | V25: =+H25-K25 -> 0
B26: 2 | C26: SERVICIOS ESPECIALES | V26: =+H26-K26 -> 0
B27: 2.1 | C27: Batimetría | D27: día | E27: 0 | F27: 783594 | G27: =E27*F27 -> 0 | K27: 0 | L27: 0 | M27: 0 | N27: =+K27*F27 -> 0 | O27: =+F27*L27 -> 0 | P27: =M27*F27 -> 0 | Q27: 0 | R27: =+N27/G$23 -> 0 | S27: =+P27/G$23 -> 0 | T27: =+G27-N27 -> 0 | V27: =+H27-K27 -> 0
B28: 2.2 | C28: Detección de Interferencias | D28: día | E28: 0 | F28: 844721 | G28: =E28*F28 -> 0 | K28: =+L28+M28 -> 0 | L28: 0 | M28: 0 | N28: =+O28+P28 -> 0 | O28: =+F28*L28 -> 0 | P28: =M28*F28 -> 0 | Q28: 0 | R28: 0 | S28: =+P28/G$23 -> 0 | T28: =+G28-N28 -> 0 | V28: =+H28-K28 -> 0
B29: 3 | C29: EQUIPOS | V29: =+H29-K29 -> 0
B30: 3.1 | C30: GPS Geodésico tiempo real | D30: día | E30: 0 | F30: 17374 | G30: =E30*F30 -> 0 | H30: =+'NOC-1'!L18 -> 0 | K30: =+L30+M30 -> 0 | L30: 0 | M30: 0 | N30: =+O30+P30 -> 0 | O30: =+F30*L30 -> 0 | P30: =M30*F30 -> 0 | Q30: 0 | R30: 0 | S30: 0 | T30: =+J30-N30 -> 0 | V30: =+H30-K30 -> 0
B31: 3.2 | C31: Estación Total | D31: día | E31: 6 | F31: 12826 | G31: =E31*F31 -> 76956 | H31: =+'NOC-1'!L19 -> 8 | J31: =+H31*F31 -> 102608 | K31: =+L31+M31 -> 8 | L31: 0 | M31: 8 | N31: =+O31+P31 -> 102608 | O31: =+F31*L31 -> 0 | P31: =M31*F31 -> 102608 | Q31: =+O31/G$31 -> 0 | R31: =+N31/J$31 -> 1 | S31: =+P31/J$31 -> 1 | T31: =+J31-N31 -> 0 | V31: =+H31-K31 -> 0
B32: 3.3 | C32: Nivel de Ingeniero | D32: día | E32: 6 | F32: 2664 | G32: =E32*F32 -> 15984 | H32: =+'NOC-1'!L20 -> 8 | J32: =+H32*F32 -> 21312 | K32: =+L32+M32 -> 8 | L32: 0 | M32: 8 | N32: =+O32+P32 -> 21312 | O32: =+F32*L32 -> 0 | P32: =M32*F32 -> 21312 | Q32: =+O32/F$25 -> 0 | R32: =+N32/J$32 -> 1 | S32: =+P32/J$32 -> 1 | T32: =+J32-N32 -> 0 | V32: =+H32-K32 -> 0
B33: 3.4 | C33: Nivel de Ingeniero de alta precisión | D33: día | E33: 0 | F33: 7661 | G33: =E33*F33 -> 0 | H33: =+'NOC-1'!L21 -> 0 | K33: =+L33+M33 -> 0 | L33: 0 | M33: 0 | N33: =+K33*F33 -> 0 | O33: =+F33*L33 -> 0 | P33: =M33*F33 -> 0 | Q33: =+O33/F$25 -> 0 | R33: =+N33/G$23 -> 0 | S33: 0 | T33: =+J33-N33 -> 0 | V33: =+H33-K33 -> 0
B34: 3.5 | C34: Escáner Láser Estructural | D34: día | E34: 6 | F34: 248036 | G34: =+F34*E34 -> 1488216 | H34: =+'NOC-1'!L22 -> 8 | J34: =+H34*F34 -> 1984288 | K34: =+L34+M34 -> 8 | L34: 0 | M34: 8 | N34: =+K34*F34 -> 1984288 | O34: =+F34*L34 -> 0 | P34: =M34*F34 -> 1984288 | Q34: =+O34/F$25 -> 0 | R34: =+N34/J$34 -> 1 | S34: =+P34/J$34 -> 1 | T34: =+J34-N34 -> 0 | V34: =+H34-K34 -> 0
B35: 3.6 | C35: Escáner Terrestre | D35: día | E35: 0 | F35: 127218 | G35: =E35*F35 -> 0 | H35: =+'NOC-1'!L23 -> 0 | K35: =+L35+M35 -> 0 | L35: 0 | M35: 0 | N35: =+K35*F35 -> 0 | O35: =+F35*L35 -> 0 | P35: =M35*F35 -> 0 | Q35: =+O35/F$25 -> 0 | R35: =+N35/G$23 -> 0 | S35: 0 | T35: =+J35-N35 -> 0 | V35: =+H35-K35 -> 0
B36: 3.7 | C36: Dron Multirrotor | D36: día | E36: 0 | F36: 61059 | G36: =+F36*E36 -> 0 | H36: =+'NOC-1'!L24 -> 0 | K36: =+L36+M36 -> 0 | L36: 0 | M36: 0 | N36: =+K36*F36 -> 0 | O36: =+F36*L36 -> 0 | P36: =M36*F36 -> 0 | Q36: =+O36/F$25 -> 0 | R36: =+N36/G$23 -> 0 | S36: 0 | T36: =+J36-N36 -> 0 | V36: =+H36-K36 -> 0
B37: 3.8 | C37: Dron Ala Fija | D37: día | E37: 0 | F37: 42702 | G37: =E37*F37 -> 0 | H37: =+'NOC-1'!L25 -> 0 | K37: =+L37+M37 -> 0 | L37: 0 | M37: 0 | N37: =+K37*F37 -> 0 | O37: =+F37*L37 -> 0 | P37: =M37*F37 -> 0 | Q37: =+O37/F$25 -> 0 | R37: =+N37/G$23 -> 0 | S37: 0 | T37: =+J37-N37 -> 0 | V37: =+H37-K37 -> 0
B38: 4 | C38: SERVICIOS DE LABORATORIO | V38: =+H38-K38 -> 0
B39: 4.1 | C39: Servicios de Laboratorio | D39: Valor | E39: 0 | F39: 0 | G39: =E39*F39 -> 0 | K39: =+L39+M39 -> 0 | L39: 0 | M39: 0 | N39: 0 | O39: 0 | P39: 0 | Q39: =+O39/F$25 -> 0 | R39: =+N39/G$23 -> 0 | S39: 0 | T39: =+J39-N39 -> 0 | V39: =+H39-K39 -> 0
B40: 4.2 | C40: Gestion (5%) | D40: Valor | E40: 0.05 | F40: =+G40 -> 0 | G40: =E40*F39 -> 0 | K40: =+L40+M40 -> 0 | L40: 0 | M40: 0 | N40: 0 | O40: 0 | P40: =+P39*3% -> 0 | Q40: =+O40/F$25 -> 0 | R40: =+N40/G$23 -> 0 | S40: 0 | T40: =+J40-N40 -> 0 | V40: =+H40-K40 -> 0 | W40: =+P39*3% -> 0
B41: 5 | C41: GASTOS DE APOYO A TARIFA CONVENIDA | V41: =+H41-K41 -> 0
B42: 5.1 | C42: Vehículo Petrolero Tracción Doble Permanente | D42: mes | E42: 0 | F42: 1778910 | G42: 587040 | H42: =+'NOC-1'!L30 -> 0.43 | J42: =+H42*F42 -> 764931.3 | K42: =+L42+M42 -> 0.43 | L42: 0 | M42: 0.43 | N42: =+K42*F42 -> 764931.3 | O42: 0 | P42: =+N42 -> 764931.3 | Q42: =+O42/G$42 -> 0 | R42: =+N42/J$42 -> 1 | S42: =+P42/J$42 -> 1 | T42: =+J42-N42 -> 0 | V42: =+H42-K42 -> 0
B43: 6 | C43: GASTOS DE APOYO A COSTO EFECTIVO | V43: =+H43-K43 -> 0
B44: 6.1 | C44: Gastos Reembolsables | D44: Valor | E44: 0 | F44: 40000000 | G44: =E44*F44 -> 0 | K44: 0 | L44: 0 | M44: 0 | N44: =+K44*F44 -> 0 | O44: =+F44*L44 -> 0 | P44: =M44*F44 -> 0 | Q44: =+O44/F$42 -> 0 | R44: =+N44/G$42 -> 0 | S44: 0 | T44: =+J44-N44 -> 0 | V44: =+H44-K44 -> 0
B45: 7 | C45: IMPLEMENTACIÓN MITIGACIÓN EMERGENCIA SANITARIA | G45: =E45*F45 -> 0 | V45: =+H45-K45 -> 0
B46: 7.1 | C46: Medidas COVID-19 / SIGO-EES-001 (Desglose en Formulario ECO-8) | D46: Valor | E46: 0 | F46: 3387136 | G46: =E46*F46 -> 0 | K46: 0 | L46: 0 | M46: 0 | N46: =+K46*F46 -> 0 | O46: =+F46*L46 -> 0 | P46: =M46*F46 -> 0 | Q46: =+O46/F$46 -> 0 | R46: =+N46/G$42 -> 0 | S46: 0 | T46: =+J46-N46 -> 0 | V46: =+H46-K46 -> 0
C47: SUBTOTAL CONTRATO BASE | G47: =+G23+G25+G31+G32+G34+G42 -> 7282646 | J47: =+J42+J34+J32+J31+J25+J23 -> 9793669.3 | L47: =+L30 -> 0 | N47: =SUM(N23:N46) -> 9793669.3 | O47: =O21 -> 0 | P47: =P21 -> 9793669.3 | T47: =T21 -> 0 | W47: =+T47+P47 -> 9793669.3
C50: TOTAL ESTIMADO | G50: =+G47 -> 7282646 | N50: =+N47 -> 9793669.3 | P50: =+P47 -> 9793669.3
...

Sheet Cuadro Control
B2: VALOR CONTRATO (ODS) INICIAL : | C2: $ | D2: =+'CARATULA EP '!J30 -> 7282646
B3: NOC-1 : | C3: $ | D3: 0
B4: NOC-2 : | C4: $ | D4: 0
B5: NOC-3 : | C5: $ | D5: 0
B6: VALOR TOTAL DEL CONTRATO : | C6: $ | D6: =+D2+D3+D4 -> 7282646
E8: TOTAL | F8: Servicios Topografía | G8: Servicio de Laboratorio | H8: Gasto de Apoyo a Tarifa Convenida | I8: Gasto de Apoyo a Costo Efectivo
B10: Valor Cobrado Hasta la Fecha (Sin Reajuste) : | D10: $ | E10: =+'EDP 001'!P47 -> 9793669.3 | F10: =+'EDP 001'!P23+'EDP 001'!P25 -> 6920530 | G10: =+'[2]EDP 001'!N39+'[2]EDP 001'!N40 -> 0 | H10: =+'EDP 001'!N30+'EDP 001'!N31+'EDP 001'!N42 -> 867539.3 | I10: ='[3]EP 001'!O33 -> 0 | J10: =+F10+H10+G10 -> 7788069.3
B11: Valor Facturado Acumulado Anterior : | D11: $ | J11: =+F11+H11+G11 -> 0
B12: Valor del Presente Estado de Pago (Sin Reajuste) : | D12: $ | E12: =+'EDP 001'!P47 -> 9793669.3 | F12: =+'EDP 001'!P23+'EDP 001'!P25 -> 6920530 | H12: =+'EDP 001'!P30+'EDP 001'!P31+'EDP 001'!P42 -> 867539.3 | J12: =+H12+F12+G12 -> 7788069.3
B13: Índice de Reajustabilidad (2023) | D13: % | J13: =+F13+H13 -> 0
B14: Reajuste Presente Estado de Pago | D14: $ | J14: =+F14+H14 -> 0
B15: Valor Presente Estado de Pago (Con Reajuste) | D15: $ | E15: =+'EDP 001'!P47 -> 9793669.3 | F15: =F12+F14 -> 6920530 | H15: =H12+H14 -> 867539.3 | J15: =+F15+H15+G15 -> 7788069.3
B16: 19% IVA | D16: $ | E16: =(E15-I15)*19% -> 1860797.2 | J16: =+F16+H16 -> 0
B17: Líquido a Pagar | D17: $ | E17: =+E15+E16 -> 11654466
E19: Valor Cartula | F19: =+'CARATULA EP '!J55 -> 11654466 | G19: =IF(E17=F19,"OK","ERROR") -> OK
E20: Valor Formulario | F20: =+'EDP 001'!P56 -> 11654466 | G20: =IF(E17=F20,"OK","ERROR") -> OK

Sheet NOC-1
B3: SERVICIOS DE TOPOGRAFÍA, DETECCIÓN DE INTERFERENCIAS Y LABORATORIO
B5: ORDEN DE CAMBIO Nº 01 ODS Nº 01
F7: Cotizacion | J7: Modificacion
B8: N° | C8: DESCRIPCION | D8: UN. | F8: PRECIO UNITARIO | G8: ODS | J8: ORDEN DE CAMBIO 1 | L8: ODS MODIFICADA
G9: CANTIDAD | H9: TOTAL | J9: CANTIDAD | K9: TOTAL | L9: CANTIDAD | M9: TOTAL
B10: 1. | C10: Servicios Profesionales
B11: 1.1. | C11: Ingeniero Geomensor | D11: HH | F11: 30379 | G11: 110 | H11: =+G11*F11 -> 3341690 | J11: =20+20 -> 40 | K11: =+J11*F11 -> 1215160 | L11: =+G11+J11 -> 150 | M11: =+H11+K11 -> 4556850
B12: 1.2. | C12: Topógrafo | D12: HH | F12: 22998 | G12: 0 | H12: =+G12*F12 -> 0 | J12: 0 | K12: =+J12*F12 -> 0 | L12: =+G12+J12 -> 0 | M12: =+H12+K12 -> 0
B13: 1.3. | C13: Alarife | D13: HH | F13: 14773 | G13: 120 | H13: =+G13*F13 -> 1772760 | J13: 40 | K13: =+J13*F13 -> 590920 | L13: =+G13+J13 -> 160 | M13: =+H13+K13 -> 2363680
B14: 2. | C14: Servicios Especiales | M14: =+H14+K14 -> 0
B15: 2.1. | C15: Batimetría | D15: día | F15: 783594 | G15: 0 | H15: =+G15*F15 -> 0 | J15: 0 | K15: =+J15*F15 -> 0 | L15: =+G15+J15 -> 0 | M15: =+H15+K15 -> 0
B16: 2.2. | C16: Detección de Interferencias | D16: día | F16: 844721 | G16: 0 | H16: =+G16*F16 -> 0 | J16: 0 | K16: =+J16*F16 -> 0 | L16: =+G16+J16 -> 0 | M16: =+H16+K16 -> 0
B17: 3. | C17: Equipos | M17: =+H17+K17 -> 0
B18: 3.1. | C18: GPS Geodésico tiempo real | D18: día | F18: 17374 | G18: 0 | H18: =+G18*F18 -> 0 | J18: 0 | K18: =+J18*F18 -> 0 | L18: =+G18+J18 -> 0 | M18: =+H18+K18 -> 0
B19: 3.2. | C19: Estación Total | D19: día | F19: 12826 | G19: 6 | H19: =+G19*F19 -> 76956 | J19: 2 | K19: =+J19*F19 -> 25652 | L19: =+G19+J19 -> 8 | M19: =+H19+K19 -> 102608
B20: 3.3. | C20: Nivel de Ingeniero | D20: día | F20: 2664 | G20: 6 | H20: =+G20*F20 -> 15984 | J20: 2 | K20: =+J20*F20 -> 5328 | L20: =+G20+J20 -> 8 | M20: =+H20+K20 -> 21312
B21: 3.4. | C21: Nivel de Ingeniero de alta precisión | D21: día | F21: 7661 | G21: 0 | H21: =+G21*F21 -> 0 | J21: 0 | K21: =+J21*F21 -> 0 | L21: =+G21+J21 -> 0 | M21: =+H21+K21 -> 0
B22: 3.5. | C22: Escáner Láser Estructural | D22: día | F22: 248036 | G22: 6 | H22: =+G22*F22 -> 1488216 | J22: 2 | K22: =+J22*F22 -> 496072 | L22: =+G22+J22 -> 8 | M22: =+H22+K22 -> 1984288
B23: 3.6. | C23: Escáner Láser Terrestre | D23: día | F23: 127218 | G23: 0 | H23: =+G23*F23 -> 0 | J23: 0 | K23: =+J23*F23 -> 0 | L23: =+G23+J23 -> 0 | M23: =+H23+K23 -> 0
B24: 3.7. | C24: Drone Multirrotor | D24: día | F24: 61059 | G24: 0 | H24: =+G24*F24 -> 0 | J24: 0 | K24: =+J24*F24 -> 0 | L24: =+G24+J24 -> 0 | M24: =+H24+K24 -> 0
B25: 3.8. | C25: Drone Ala Fija | D25: día | F25: 42702 | G25: 0 | H25: =+G25*F25 -> 0 | J25: 0 | K25: =+J25*F25 -> 0 | L25: =+G25+J25 -> 0 | M25: =+H25+K25 -> 0
B26: 4. | C26: Servicios de Laboratorio | M26: =+H26+K26 -> 0
B27: 4.1. | C27: Servicios de Laboratorio | D27: Valor | F27: 0 | G27: 0 | H27: =+G27*F27 -> 0 | J27: 0 | K27: =+J27*F27 -> 0 | L27: =+G27+J27 -> 0 | M27: =+H27+K27 -> 0
B28: 4.2. | C28: Gestion Geosupport (5%) | D28: Valor | F28: 0 | G28: 0 | H28: =+G28*F28 -> 0 | J28: 0 | K28: =+J28*F28 -> 0 | L28: =+G28+J28 -> 0 | M28: =+H28+K28 -> 0
B29: 5. | C29: Gastos de Apoyo a Tarifa convenida: | E29: 2.666 | M29: =+H29+K29 -> 0
B30: 5.1 | C30: Vehículo Petrolero Tracción Doble | D30: Mes | E30: =+E29-#REF! -> #REF! | F30: 1778910 | G30: 0.33 | H30: =+G30*F30 -> 587040.3 | J30: 0.1 | K30: =+J30*F30 -> 177891 | L30: =+G30+J30 -> 0.43 | M30: =+H30+K30 -> 764931.3
B31: 6. | C31: Gastos de Apoyo a costo efectivo | M31: =+H31+K31 -> 0
B32: 6.1 | C32: Gastos Reembolsables | D32: Valor | F32: 40000000 | G32: 0 | H32: =+G32*F32 -> 0 | J32: 0 | K32: =+J32*F32 -> 0 | L32: =+G32+J32 -> 0 | M32: =+H32+K32 -> 0
B33: 7 | C33: IMPLEMENTACIÓN MITIGACIÓN EMERGENCIA SANITARIA | M33: =+H33+K33 -> 0
B34: 7.1 | C34: Medidas COVID-19 / SIGO-EES-001 (Desglose en Formulario ECO-8) | D34: Valor | F34: 3387136 | G34: 0 | H34: =+G34*F34 -> 0 | J34: 0 | K34: =+J34*F34 -> 0 | L34: =+G34+J34 -> 0 | M34: =+H34+K34 -> 0
C36: TOTAL | H36: =SUM(H11:H35) -> 7282646.3 | I36: =+#REF!+#REF!+#REF! -> #REF! | K36: =SUM(K10:K35) -> 2511023 | M36: =SUM(M11:M35) -> 9793669.3 | N36: =+K36+H36 -> 9793669.3
J38: 0.13333333
